Workbook

Sheet Compliance Summary
A1: CMDB Compliance Summary — CSDM v5 Enhanced (3K, Moderate >70%)
A3: Overall Metrics
A4: Metric | B4: Value
A5: Total CIs | B5: =COUNTA('CMDB CIs'!A2:A3001)
A6: Compliant | B6: =COUNTIF('CMDB CIs'!AE2:AE3001,"Compliant")
A7: Partially Compliant | B7: =COUNTIF('CMDB CIs'!AE2:AE3001,"Partially Compliant")
A8: Non-Compliant | B8: =COUNTIF('CMDB CIs'!AE2:AE3001,"Non-Compliant")
A9: Overall Compliance % | B9: =B6/B5
A10: Average Compliance Score | B10: =AVERAGE('CMDB CIs'!AD2:AD3001)
A13: Compliance by Business Application (CSDM v5)
A14: Business Application | B14: Total | C14: Compliant | D14: Non-Compliant | E14: Compliance %
A15: Workday | B15: =COUNTIF('CMDB CIs'!Z2:Z3001,A15) | C15: =COUNTIFS('CMDB CIs'!Z2:Z3001,A15,'CMDB CIs'!AE2:AE3001,"Compliant") | D15: =COUNTIFS('CMDB CIs'!Z2:Z3001,A15,'CMDB CIs'!AE2:AE3001,"Non-Compliant") | E15: =IFERROR(C15/B15,0)
A16: SAP ERP | B16: =COUNTIF('CMDB CIs'!Z2:Z3001,A16) | C16: =COUNTIFS('CMDB CIs'!Z2:Z3001,A16,'CMDB CIs'!AE2:AE3001,"Compliant") | D16: =COUNTIFS('CMDB CIs'!Z2:Z3001,A16,'CMDB CIs'!AE2:AE3001,"Non-Compliant") | E16: =IFERROR(C16/B16,0)
A17: Microsoft 365 | B17: =COUNTIF('CMDB CIs'!Z2:Z3001,A17) | C17: =COUNTIFS('CMDB CIs'!Z2:Z3001,A17,'CMDB CIs'!AE2:AE3001,"Compliant") | D17: =COUNTIFS('CMDB CIs'!Z2:Z3001,A17,'CMDB CIs'!AE2:AE3001,"Non-Compliant") | E17: =IFERROR(C17/B17,0)
A18: Adobe | B18: =COUNTIF('CMDB CIs'!Z2:Z3001,A18) | C18: =COUNTIFS('CMDB CIs'!Z2:Z3001,A18,'CMDB CIs'!AE2:AE3001,"Compliant") | D18: =COUNTIFS('CMDB CIs'!Z2:Z3001,A18,'CMDB CIs'!AE2:AE3001,"Non-Compliant") | E18: =IFERROR(C18/B18,0)
A19: Oracle Fusion ERP | B19: =COUNTIF('CMDB CIs'!Z2:Z3001,A19) | C19: =COUNTIFS('CMDB CIs'!Z2:Z3001,A19,'CMDB CIs'!AE2:AE3001,"Compliant") | D19: =COUNTIFS('CMDB CIs'!Z2:Z3001,A19,'CMDB CIs'!AE2:AE3001,"Non-Compliant") | E19: =IFERROR(C19/B19,0)
A22: Compliance by CI Class
A23: CI Class | B23: Total | C23: Compliant | D23: Non-Compliant | E23: Compliance %
A24: cmdb_ci_pc_hardware | B24: =COUNTIF('CMDB CIs'!C2:C3001,A24) | C24: =COUNTIFS('CMDB CIs'!C2:C3001,A24,'CMDB CIs'!AE2:AE3001,"Compliant") | D24: =COUNTIFS('CMDB CIs'!C2:C3001,A24,'CMDB CIs'!AE2:AE3001,"Non-Compliant") | E24: =IFERROR(C24/B24,0)
A25: cmdb_ci_linux_server | B25: =COUNTIF('CMDB CIs'!C2:C3001,A25) | C25: =COUNTIFS('CMDB CIs'!C2:C3001,A25,'CMDB CIs'!AE2:AE3001,"Compliant") | D25: =COUNTIFS('CMDB CIs'!C2:C3001,A25,'CMDB CIs'!AE2:AE3001,"Non-Compliant") | E25: =IFERROR(C25/B25,0)
A26: cmdb_ci_win_server | B26: =COUNTIF('CMDB CIs'!C2:C3001,A26) | C26: =COUNTIFS('CMDB CIs'!C2:C3001,A26,'CMDB CIs'!AE2:AE3001,"Compliant") | D26: =COUNTIFS('CMDB CIs'!C2:C3001,A26,'CMDB CIs'!AE2:AE3001,"Non-Compliant") | E26: =IFERROR(C26/B26,0)
A27: cmdb_ci_vmware_instance | B27: =COUNTIF('CMDB CIs'!C2:C3001,A27) | C27: =COUNTIFS('CMDB CIs'!C2:C3001,A27,'CMDB CIs'!AE2:AE3001,"Compliant") | D27: =COUNTIFS('CMDB CIs'!C2:C3001,A27,'CMDB CIs'!AE2:AE3001,"Non-Compliant") | E27: =IFERROR(C27/B27,0)
A28: cmdb_ci_db_instance | B28: =COUNTIF('CMDB CIs'!C2:C3001,A28) | C28: =COUNTIFS('CMDB CIs'!C2:C3001,A28,'CMDB CIs'!AE2:AE3001,"Compliant") | D28: =COUNTIFS('CMDB CIs'!C2:C3001,A28,'CMDB CIs'!AE2:AE3001,"Non-Compliant") | E28: =IFERROR(C28/B28,0)
A29: cmdb_ci_web_server | B29: =COUNTIF('CMDB CIs'!C2:C3001,A29) | C29: =COUNTIFS('CMDB CIs'!C2:C3001,A29,'CMDB CIs'!AE2:AE3001,"Compliant") | D29: =COUNTIFS('CMDB CIs'!C2:C3001,A29,'CMDB CIs'!AE2:AE3001,"Non-Compliant") | E29: =IFERROR(C29/B29,0)
A30: cmdb_ci_app_server | B30: =COUNTIF('CMDB CIs'!C2:C3001,A30) | C30: =COUNTIFS('CMDB CIs'!C2:C3001,A30,'CMDB CIs'!AE2:AE3001,"Compliant") | D30: =COUNTIFS('CMDB CIs'!C2:C3001,A30,'CMDB CIs'!AE2:AE3001,"Non-Compliant") | E30: =IFERROR(C30/B30,0)
A31: cmdb_ci_ip_switch | B31: =COUNTIF('CMDB CIs'!C2:C3001,A31) | C31: =COUNTIFS('CMDB CIs'!C2:C3001,A31,'CMDB CIs'!AE2:AE3001,"Compliant") | D31: =COUNTIFS('CMDB CIs'!C2:C3001,A31,'CMDB CIs'!AE2:AE3001,"Non-Compliant") | E31: =IFERROR(C31/B31,0)
A32: cmdb_ci_service_auto | B32: =COUNTIF('CMDB CIs'!C2:C3001,A32) | C32: =COUNTIFS('CMDB CIs'!C2:C3001,A32,'CMDB CIs'!AE2:AE3001,"Compliant") | D32: =COUNTIFS('CMDB CIs'!C2:C3001,A32,'CMDB CIs'!AE2:AE3001,"Non-Compliant") | E32: =IFERROR(C32/B32,0)
A33: cmdb_ci_storage_device | B33: =COUNTIF('CMDB CIs'!C2:C3001,A33) | C33: =COUNTIFS('CMDB CIs'!C2:C3001,A33,'CMDB CIs'!AE2:AE3001,"Compliant") | D33: =COUNTIFS('CMDB CIs'!C2:C3001,A33,'CMDB CIs'!AE2:AE3001,"Non-Compliant") | E33: =IFERROR(C33/B33,0)
A34: cmdb_ci_ip_router | B34: =COUNTIF('CMDB CIs'!C2:C3001,A34) | C34: =COUNTIFS('CMDB CIs'!C2:C3001,A34,'CMDB CIs'!AE2:AE3001,"Compliant") | D34: =COUNTIFS('CMDB CIs'!C2:C3001,A34,'CMDB CIs'!AE2:AE3001,"Non-Compliant") | E34: =IFERROR(C34/B34,0)
A35: cmdb_ci_ip_firewall | B35: =COUNTIF('CMDB CIs'!C2:C3001,A35) | C35: =COUNTIFS('CMDB CIs'!C2:C3001,A35,'CMDB CIs'!AE2:AE3001,"Compliant") | D35: =COUNTIFS('CMDB CIs'!C2:C3001,A35,'CMDB CIs'!AE2:AE3001,"Non-Compliant") | E35: =IFERROR(C35/B35,0)

Sheet CMDB CIs
A1: sys_id | B1: name | C1: sys_class_name | D1: asset_tag | E1: serial_number | F1: manufacturer | G1: model_id | H1: location | I1: environment | J1: install_status | K1: operational_status | L1: ip_address | M1: os | N1: os_version | O1: cpu_count | P1: ram_gb | Q1: disk_gb | R1: assigned_to | S1: assignment_group | T1: support_group | U1: owned_by | V1: managed_by | W1: first_discovered | X1: last_discovered | Y1: discovery_source | Z1: business_application | AA1: business_service | AB1: technical_application | AC1: technical_service | AD1: compliance_score | AE1: compliance_status | AF1: compliance_issues
A2: 20a9d63b44e64a69b8e59ef5333cde02 | B2: app-prd-ben-00001 | C2: cmdb_ci_app_server | D2: AST-71607316 | E2: SN2640065984 | F2: Apache Foundation | G2: Tomcat 10 | H2: Bengaluru-DC1 | I2: Production | J2: Installed | K2: Operational | L2: 10.38.96.24 | O2: 16 | P2: 256 | Q2: 500 | S2: Java Platform Team | T2: Java Platform Team | U2: Arjun Wilson | V2: Deepika Krishnan | W2: 2022-10-11 11:09:17 | X2: 2025-03-06 11:09:17 | Y2: CSV Import | Z2: SAP ERP | AA2: Record-to-Report | AB2: SAP S/4HANA Production | AC2: SAP Gateway OData Service | AD2: 90 | AE2: Compliant | AF2: Stale discovery (>90 days)
A3: d94fa50212a241eabde622d94b68d03b | B3: PC-0100001 | C3: cmdb_ci_pc_hardware | D3: AST-42754321 | E3: SN3808214504 | F3: Dell | G3: OptiPlex 7090 | J3: Installed | K3: Operational | L3: 10.158.35.59 | O3: 8 | P3: 32 | Q3: 1000 | R3: Kavita Reddy | S3: End User Computing | T3: End User Computing | U3: Suresh Jones | V3: Pooja Joshi | W3: 2023-12-09 11:09:17 | X3: 2026-05-09 11:09:17 | Y3: Service Mapping | Z3: Microsoft 365 | AA3: Internal Communications | AB3: SharePoint Online | AC3: Microsoft Endpoint Manager | AD3: 80 | AE3: Compliant | AF3: Missing environment; Missing location
A4: 6ad7d822d0cd4a96981276ba5996a37f | B4: sw-dev-hyd-00001 | C4: cmdb_ci_ip_switch | D4: AST-79713742 | F4: Cisco | G4: Nexus 9336C-FX2 | H4: Hyderabad-DC1 | I4: Development | J4: Installed | K4: Operational | L4: 10.138.137.94 | S4: Network Operations | T4: Network Operations | V4: Anand Iyer | W4: 2025-09-27 11:09:17 | X4: 2026-05-17 11:09:17 | Y4: Manual | Z4: Microsoft 365 | AA4: Internal Communications | AB4: Exchange Online | AC4: Microsoft Endpoint Manager | AD4: 80 | AE4: Compliant | AF4: Missing serial_number; Missing owned_by
A5: 1e4e075f495046b49ff3f15508315a3a | B5: PC-0100002 | C5: cmdb_ci_pc_hardware | D5: AST-38243358 | E5: SN5585622913 | F5: HP | G5: EliteBook 840 G10 | H5: Gurgaon-Office | I5: UAT | J5: Retired | K5: Operational | L5: 10.171.14.253 | O5: 6 | P5: 32 | Q5: 256 | R5: Ravi Brown | S5: Desktop Support | T5: Desktop Support | U5: Robert Shetty | V5: Deepika Krishnan | W5: 2023-09-12 11:09:17 | X5: 2026-05-03 11:09:17 | Y5: CSV Import | Z5: Microsoft 365 | AA5: Video Conferencing | AB5: SharePoint Online | AC5: Entra ID (Azure AD) | AD5: 100 | AE5: Compliant | AF5: None
A6: f4cbcbac109d4fe5bc86502f36ced604 | B6: PC-0100003 | C6: cmdb_ci_pc_hardware | D6: AST-46274203 | E6: SN4001009295 | F6: Lenovo | G6: ThinkPad T14 | H6: Pune-Office | I6: Production | J6: Installed | K6: Operational | L6: 10.35.4.13 | O6: 6 | P6: 8 | Q6: 256 | R6: Pooja Verma | S6: Desktop Support | T6: Desktop Support | U6: Rajesh Krishnan | V6: Robert Jones | W6: 2024-11-01 11:09:17 | X6: 2026-05-06 11:09:17 | Y6: CSV Import | Z6: Workday | AA6: HR Self-Service | AB6: Workday Recruiting Portal | AC6: HR Data Integration Bus | AD6: 100 | AE6: Compliant | AF6: None
A7: c6e65be05a7f49f39ff41f2b433d1b89 | B7: PC-0100004 | C7: cmdb_ci_pc_hardware | D7: AST-38725383 | E7: SN5348293994 | J7: In Maintenance | K7: DR Standby | L7: 10.50.52.62 | O7: 6 | P7: 32 | Q7: 256 | R7: Rohit Desai | S7: IT Service Desk | T7: IT Service Desk | U7: Meera Rao | V7: Aditya Mehta | W7: 2024-01-10 11:09:17 | X7: 2026-05-12 11:09:17 | Y7: CSV Import | Z7: Microsoft 365 | AA7: Internal Communications | AB7: Microsoft Purview | AC7: Microsoft Graph API | AD7: 60 | AE7: Partially Compliant | AF7: Missing manufacturer; Missing environment; Missing location; Missing model_id
A8: b807893685aa45e3b1a7a2d1c79da12b | B8: win-prd-pun-00001 | C8: cmdb_ci_win_server | D8: AST-88130076 | E8: SN6030620624 | F8: HPE | G8: ProLiant DL380 Gen10 | H8: Pune-Office | I8: Production | J8: Installed | K8: DR Standby | L8: 10.35.79.37 | M8: Windows Server | N8: 2022 Datacenter | O8: 96 | P8: 64 | Q8: 16000 | S8: Windows Admins | T8: Windows Admins | U8: Shreya Banerjee | V8: Neha Wilson | W8: 2024-12-07 11:09:17 | X8: 2026-05-12 11:09:17 | Y8: Manual | Z8: SAP ERP | AA8: Inventory & Warehouse | AB8: SAP S/4HANA Sales | AC8: SAP Solution Manager | AD8: 100 | AE8: Compliant | AF8: None
A9: 071eeff51e16479fb41ed4b1d6aaf559 | B9: PC-0100005 | C9: cmdb_ci_pc_hardware | D9: AST-90517524 | E9: SN2001360032 | F9: Dell | G9: OptiPlex 7090 | H9: Bengaluru-DC1 | I9: Test | J9: Installed | K9: Operational | L9: 10.139.237.94 | O9: 4 | P9: 8 | Q9: 256 | R9: John Singh | S9: IT Service Desk | T9: IT Service Desk | U9: Meera Mehta | V9: Shreya Desai | W9: 2023-09-11 11:09:17 | X9: 2026-05-20 11:09:17 | Y9: Manual | Z9: Microsoft 365 | AA9: Enterprise Email | AB9: Exchange Online | AC9: Entra ID (Azure AD) | AD9: 100 | AE9: Compliant | AF9: None
A10: 57403e0f073740958acd08b56378d6a2 | B10: app-uat-mum-00002 | C10: cmdb_ci_app_server | F10: Oracle | G10: WebLogic 14c | I10: UAT | J10: Installed | K10: Operational | L10: 10.188.91.158 | O10: 96 | P10: 16 | Q10: 200 | S10: Middleware Admins | U10: Anand Krishnan | V10: Meera Sharma | W10: 2024-11-26 11:09:17 | X10: 2026-05-13 11:09:17 | Y10: Manual | Z10: Oracle Fusion ERP | AA10: Project Portfolio Mgmt | AB10: Oracle Fusion Risk Mgmt | AC10: Oracle Integration Cloud | AD10: 60 | AE10: Partially Compliant | AF10: Missing serial_number; Missing support_group; Missing asset_tag; Missing location
A11: c4b5999414e145dab18f33c490f9beda | B11: vm-dev-pun-00001 | C11: cmdb_ci_vmware_instance | D11: AST-42703728 | F11: VMware | G11: vSphere VM | I11: Development | J11: Installed | K11: Operational | L11: 10.117.32.94 | M11: Windows Server | N11: 2022 Standard | O11: 4 | P11: 256 | Q11: 500 | S11: Virtualization Team | V11: Emma Sharma | W11: 2024-09-21 11:09:17 | X11: 2026-05-03 11:09:17 | Y11: BMC ADDM | Z11: Adobe | AA11: Marketing Automation | AB11: Adobe Creative Cloud | AC11: Adobe Asset Service | AD11: 60 | AE11: Partially Compliant | AF11: Missing support_group; Missing owned_by; Missing serial_number; Missing location
A12: 0ff7d04ecfae46ac91492f778a97f8fd | B12: lnx-prd-ben-00001 | C12: cmdb_ci_linux_server | D12: AST-39798329 | E12: SN5512298608 | F12: HPE | G12: ProLiant DL380 Gen10 | I12: Production | K12: Operational | L12: 10.18.205.10 | M12: Oracle Linux | N12: 8.7 | O12: 24 | P12: 32 | Q12: 2000 | S12: Platform Engineering | T12: Platform Engineering | U12: Michael Patel | V12: Karthik Shetty | W12: 2023-02-07 11:09:17 | X12: 2026-05-18 11:09:17 | Y12: CSV Import | Z12: Oracle Fusion ERP | AA12: Financial Close | AB12: Oracle Fusion Procurement | AC12: Oracle Analytics Cloud | AD12: 80 | AE12: Compliant | AF12: Missing location; Missing install_status
A13: dddc891f41d3467aadebdbe49ea6c208 | B13: vm-dr-ben-00002 | C13: cmdb_ci_vmware_instance | D13: AST-65777723 | E13: SN3376802437 | F13: VMware | G13: vSphere VM | H13: Bengaluru-DC1 | I13: DR | J13: Installed | K13: Operational | L13: 10.156.48.177 | M13: Windows Server | N13: 2022 Datacenter | O13: 4 | P13: 64 | Q13: 500 | S13: Cloud Operations | T13: Cloud Operations | U13: Aditya Williams | V13: John Sharma | W13: 2024-01-05 11:09:17 | X13: 2026-05-03 11:09:17 | Y13: BMC ADDM | Z13: Oracle Fusion ERP | AA13: Risk & Compliance | AB13: Oracle Fusion Tax Reporting | AC13: Oracle REST Data Service | AD13: 100 | AE13: Compliant | AF13: None
A14: 481370c138fd4c1fb358c723eb95b2ab | B14: sw-tst-mum-00002 | C14: cmdb_ci_ip_switch | E14: SN6019219960 | F14: Cisco | G14: Catalyst 9300-48P | H14: Mumbai-DC2 | K14: Operational | L14: 10.197.175.233 | S14: Network Engineering | T14: Network Engineering | V14: Meera Patel | W14: 2023-08-12 11:09:17 | X14: 2026-05-14 11:09:17 | Y14: SCCM | Z14: Workday | AA14: Time & Attendance | AB14: Workday HCM Core | AC14: Identity Federation (SAML) | AD14: 60 | AE14: Partially Compliant | AF14: Missing asset_tag; Missing owned_by; Missing install_status; Missing environment
A15: 39fd6ccde4d845469cb0a4285cf9fd6e | B15: PC-0100006 | C15: cmdb_ci_pc_hardware | D15: AST-66050915 | E15: SN7391581182 | F15: HP | G15: EliteBook 840 G10 | H15: Bengaluru-DC2 | J15: Installed | K15: Operational | L15: 10.40.47.254 | O15: 4 | P15: 16 | Q15: 1000 | R15: Neha Joshi | S15: IT Service Desk | T15: IT Service Desk | U15: Priya Verma | V15: Kavita Banerjee | W15: 2026-01-31 11:09:17 | X15: 2026-05-09 11:09:17 | Y15: Manual | Z15: Microsoft 365 | AA15: Enterprise Email | AB15: Microsoft Teams | AC15: Microsoft Endpoint Manager | AD15: 90 | AE15: Compliant | AF15: Missing environment
A16: 8b7e2ec5609f4e96b9a2b9e099aca3fd | B16: PC-0100007 | C16: cmdb_ci_pc_hardware | D16: AST-11707806 | E16: SN9837508065 | F16: Dell | G16: OptiPlex 7090 | J16: Installed | K16: Operational | L16: 10.26.206.175 | O16: 8 | P16: 8 | Q16: 256 | R16: Anjali Kumar | S16: Desktop Support | U16: Ravi Patel | V16: Lakshmi Nair | W16: 2023-05-24 11:09:17 | X16: 2026-05-23 11:09:17 | Y16: Service Mapping | Z16: Microsoft 365 | AA16: Enterprise Email | AB16: Power Platform | AC16: Microsoft Endpoint Manager | AD16: 70 | AE16: Partially Compliant | AF16: Missing environment; Missing support_group; Missing location
A17: 516979c75f794a0dab6be89a1ed51f8a | B17: vm-prd-new-00003 | C17: cmdb_ci_vmware_instance | D17: AST-54598574 | E17: SN5025509840 | F17: VMware | G17: vSphere VM | H17: New York-DC | I17: Production | J17: Installed | K17: Operational | L17: 10.50.83.89 | M17: Red Hat Enterprise Linux | N17: 9.2 | O17: 4 | P17: 64 | Q17: 200 | S17: Cloud Operations | T17: Cloud Operations | U17: Vikram Shetty | V17: Rajesh Nair | W17: 2025-11-19 11:09:17 | X17: 2026-05-07 11:09:17 | Y17: ServiceNow Discovery | Z17: SAP ERP | AA17: Record-to-Report | AB17: SAP S/4HANA Procurement | AC17: SAP HANA Database | AD17: 100 | AE17: Compliant | AF17: None
A18: 538f73c331434f59a11254da1b246e5a | B18: PC-0100008 | C18: cmdb_ci_pc_hardware | D18: AST-29191841 | E18: SN3518001184 | F18: Dell | G18: OptiPlex 7090 | I18: Production | J18: Installed | K18: Operational | L18: 10.18.10.204 | O18: 6 | P18: 16 | Q18: 1000 | R18: Sarah Joshi | S18: End User Computing | T18: End User Computing | U18: Manish Rao | V18: James Joshi | W18: 2025-01-26 11:09:17 | X18: 2026-05-21 11:09:17 | Y18: SCCM | Z18: Microsoft 365 | AA18: Video Conferencing | AB18: OneDrive for Business | AC18: M365 Defender | AD18: 90 | AE18: Compliant | AF18: Missing location
A19: 0ded17b1c8b34b2b837d6bd66a2ecbf7 | B19: vm-pre-mum-00004 | C19: cmdb_ci_vmware_instance | D19: AST-97696385 | E19: SN7550580157 | F19: VMware | G19: vSphere VM | H19: Mumbai-DC1 | I19: Pre-Production | K19: Operational | L19: 10.196.40.177 | M19: Red Hat Enterprise Linux | N19: 8.6 | O19: 64 | P19: 16 | Q19: 500 | S19: Virtualization Team | T19: Virtualization Team | U19: Ravi Mehta | V19: Rajesh Krishnan | W19: 2022-09-24 11:09:17 | X19: 2026-04-29 11:09:17 | Y19: ServiceNow Discovery | Z19: Adobe | AA19: Content Authoring | AB19: Adobe Workfront | AC19: Adobe Asset Service | AD19: 90 | AE19: Compliant | AF19: Missing install_status
A20: 4e0101d93e5e4674ac371373f7c61d1e | B20: PC-0100009 | C20: cmdb_ci_pc_hardware | D20: AST-32365378 | E20: SN8880139493 | F20: Dell | G20: Latitude 5540 | H20: New York-DC | I20: Production | J20: Installed | K20: DR Standby | L20: 10.36.1.3 | O20: 6 | P20: 32 | Q20: 256 | R20: David Kumar | S20: End User Computing | T20: End User Computing | U20: James Patel | V20: Robert Desai | W20: 2022-12-29 11:09:17 | X20: 2026-05-13 11:09:17 | Y20: ServiceNow Discovery | Z20: Microsoft 365 | AA20: File Storage & Sync | AB20: Power Platform | AC20: Microsoft Graph API | AD20: 100 | AE20: Compliant | AF20: None
A21: 7c99c7ab3c4a4024a57e7c27e2c139ac | B21: PC-0100010 | C21: cmdb_ci_pc_hardware | D21: AST-24833479 | E21: SN1142307138 | F21: HP | G21: EliteBook 840 G10 | H21: Hyderabad-DC1 | I21: Production | J21: Installed | K21: Operational | L21: 10.15.86.21 | O21: 4 | P21: 8 | Q21: 1000 | R21: Shreya Patel | S21: Desktop Support | T21: Desktop Support | U21: Pooja Sharma | V21: Anjali Rao | W21: 2024-08-15 11:09:17 | X21: 2026-02-17 11:09:17 | Y21: Manual | Z21: Adobe | AA21: Web Analytics | AB21: Adobe Experience Manager | AC21: Adobe Asset Service | AD21: 90 | AE21: Compliant | AF21: Stale discovery (>90 days)
A22: 5612efb59cc44728aa6e781781c8dafc | B22: PC-0100011 | C22: cmdb_ci_pc_hardware | D22: AST-40012723 | E22: SN1329010027 | F22: Dell | G22: Latitude 5540 | H22: London-DR | I22: UAT | J22: Installed | K22: Operational | L22: 10.198.23.104 | O22: 6 | P22: 32 | Q22: 1000 | R22: Neha Brown | S22: End User Computing | T22: End User Computing | U22: Anand Mehta | V22: Lakshmi Nair | W22: 2024-08-08 11:09:17 | X22: 2026-05-14 11:09:17 | Y22: Service Mapping | Z22: Adobe | AA22: Marketing Automation | AB22: Adobe Campaign | AC22: Adobe Cloud Storage | AD22: 100 | AE22: Compliant | AF22: None
A23: e10f9fae60594506810ef0a1244bb29b | B23: vm-prd-hyd-00005 | C23: cmdb_ci_vmware_instance | D23: AST-64183558 | E23: SN6985738789 | F23: VMware | G23: vSphere VM | H23: Hyderabad-DC1 | I23: Production | J23: Installed | K23: Operational | L23: 10.25.199.201 | M23: Windows Server | N23: 2022 Datacenter | O23: 8 | P23: 256 | Q23: 8000 | S23: Virtualization Team | T23: Virtualization Team | U23: Kavita Sharma | V23: Anjali Banerjee | W23: 2024-12-03 11:09:17 | X23: 2026-05-03 11:09:17 | Y23: ServiceNow Discovery | Z23: Workday | AA23: Time & Attendance | AB23: Workday Payroll Engine | AC23: Identity Federation (SAML) | AD23: 100 | AE23: Compliant | AF23: None
A24: 430311f46cba4039a9b4208666d4db85 | B24: vm-prd-lon-00006 | C24: cmdb_ci_vmware_instance | D24: AST-26230649 | E24: SN8386614925 | F24: VMware | G24: vSphere VM | H24: London-DR | I24: Production | J24: Installed | K24: Operational | L24: 10.39.35.27 | M24: Windows Server | N24: 2019 Standard | O24: 24 | P24: 768 | Q24: 4000 | S24: Cloud Operations | T24: Cloud Operations | U24: Aditya Pillai | V24: Michael Banerjee | W24: 2023-02-22 11:09:17 | X24: 2026-05-15 11:09:17 | Y24: CSV Import | Z24: Adobe | AA24: Digital Asset Management | AB24: Adobe Analytics | AC24: Adobe Cloud Storage | AD24: 100 | AE24: Compliant | AF24: None
A25: d2c07f52c58546c4bb9ca258fb152cc4 | B25: vm-prd-new-00007 | C25: cmdb_ci_vmware_instance | D25: AST-67600146 | E25: SN4581183735 | F25: VMware | G25: vSphere VM | H25: New York-DC | I25: Production | J25: Installed | K25: Operational | L25: 10.47.199.193 | M25: Windows Server | N25: 2019 Standard | O25: 24 | P25: 64 | Q25: 8000 | S25: Cloud Operations | T25: Cloud Operations | U25: Arjun Wilson | V25: Ravi Taylor | W25: 2022-10-07 11:09:17 | X25: 2025-09-18 11:09:17 | Y25: ServiceNow Discovery | Z25: Oracle Fusion ERP | AA25: Risk & Compliance | AB25: Oracle Fusion Project Mgmt | AC25: Oracle Analytics Cloud | AD25: 90 | AE25: Compliant | AF25: Stale discovery (>90 days)
A26: 23893d5faf3e40518390de8216407f11 | B26: PC-0100012 | C26: cmdb_ci_pc_hardware | D26: AST-63902681 | E26: SN6272873906 | F26: Dell | G26: Latitude 5540 | H26: Mumbai-DC1 | I26: Pre-Production | J26: Installed | K26: Operational | L26: 10.89.253.65 | O26: 8 | P26: 32 | Q26: 512 | R26: Sunita Kumar | S26: Desktop Support | T26: Desktop Support | U26: Michael Rao | V26: Kavita Verma | W26: 2024-08-10 11:09:17 | X26: 2026-05-13 11:09:17 | Y26: SCCM | Z26: SAP ERP | AA26: Order-to-Cash | AB26: SAP S/4HANA Sales | AC26: SAP Solution Manager | AD26: 100 | AE26: Compliant | AF26: None
A27: 287566a05ab3459e8bfa5cede81b9121 | B27: lnx-dev-che-00002 | C27: cmdb_ci_linux_server | D27: AST-75458523 | E27: SN9642064576 | F27: HPE | G27: ProLiant DL380 Gen10 | I27: Development | J27: Installed | K27: Operational | L27: 10.191.122.90 | M27: Oracle Linux | N27: 8.7 | O27: 96 | P27: 384 | Q27: 500 | S27: Platform Engineering | U27: Anand Krishnan | V27: Aditya Sharma | W27: 2023-04-23 11:09:17 | X27: 2026-05-16 11:09:17 | Y27: Service Mapping | Z27: SAP ERP | AA27: Procure-to-Pay | AB27: SAP Fiori Launchpad | AC27: SAP Gateway OData Service | AD27: 80 | AE27: Compliant | AF27: Missing location; Missing support_group
A28: 4159763d15c94884af0990b1d0cbde10 | B28: lnx-prd-mum-00003 | C28: cmdb_ci_linux_server | D28: AST-42851197 | E28: SN7393676837 | F28: Dell EMC | I28: Production | J28: In Maintenance | L28: 10.35.128.58 | M28: Red Hat Enterprise Linux | N28: 9.2 | O28: 16 | P28: 128 | Q28: 16000 | S28: Unix Operations | T28: Unix Operations | V28: Arjun Brown | W28: 2022-04-25 11:09:17 | X28: 2026-05-22 11:09:17 | Y28: Service Mapping | Z28: Oracle Fusion ERP | AA28: Treasury Operations | AB28: Oracle Fusion Tax Reporting | AC28: Oracle Identity Cloud Service | AD28: 60 | AE28: Partially Compliant | AF28: Missing owned_by; Missing model_id; Missing operational_status; Missing location
A29: c1d4cce401df42019c6bd7695cd6783d | B29: win-pre-hyd-00002 | C29: cmdb_ci_win_server | D29: AST-71686158 | E29: SN8061808780 | F29: HPE | H29: Hyderabad-DC1 | I29: Pre-Production | J29: In Maintenance | K29: Operational | L29: 10.139.75.236 | M29: Windows Server | N29: 2022 Datacenter | O29: 64 | P29: 64 | Q29: 2000 | S29: Platform Engineering | T29: Platform Engineering | V29: Anand Taylor | W29: 2025-07-05 11:09:17 | X29: 2026-05-19 11:09:17 | Y29: ServiceNow Discovery | Z29: SAP ERP | AA29: Inventory & Warehouse | AB29: SAP S/4HANA Finance | AC29: SAP NetWeaver Application Server | AD29: 80 | AE29: Compliant | AF29: Missing owned_by; Missing model_id
A30: 4013c7b20e3a4404907016e86603339e | B30: app-uat-sin-00003 | C30: cmdb_ci_app_server | D30: AST-77269965 | F30: Apache Foundation | G30: Tomcat 10 | H30: Singapore-DC | I30: UAT | K30: DR Standby | L30: 10.164.38.220 | O30: 32 | P30: 32 | Q30: 500 | S30: Java Platform Team | T30: Java Platform Team | U30: Rajesh Iyer | V30: Lisa Banerjee | W30: 2024-07-08 11:09:17 | X30: 2026-05-15 11:09:17 | Y30: Service Mapping | Z30: Oracle Fusion ERP | AA30: Project Portfolio Mgmt | AB30: Oracle Fusion Financials | AC30: Oracle Analytics Cloud | AD30: 80 | AE30: Compliant | AF30: Missing serial_number; Missing install_status
A31: 4478f9f9288643eb834805d315940dca | B31: PC-0100013 | C31: cmdb_ci_pc_hardware | D31: AST-46254895 | E31: SN8581434181 | F31: Apple | G31: MacBook Pro 14" | H31: New York-DC | I31: Production | J31: Installed | K31: Operational | L31: 10.12.209.146 | O31: 6 | P31: 16 | Q31: 1000 | R31: Michael Verma | S31: End User Computing | T31: End User Computing | U31: Lisa Krishnan | V31: Michael Rao | W31: 2023-09-30 11:09:17 | X31: 2026-05-23 11:09:17 | Y31: SCCM | Z31: Microsoft 365 | AA31: Video Conferencing | AB31: Power Platform | AC31: M365 Defender | AD31: 100 | AE31: Compliant | AF31: None
A32: 0556068ef88548b49a028a9fa9d18a5e | B32: lnx-uat-hyd-00004 | C32: cmdb_ci_linux_server | D32: AST-57630460 | E32: SN7862013536 | F32: HPE | G32: ProLiant DL360 Gen10 | H32: Hyderabad-DC1 | I32: UAT | J32: Installed | K32: DR Standby | L32: 10.80.236.243 | M32: Red Hat Enterprise Linux | N32: 9.2 | O32: 64 | P32: 384 | Q32: 16000 | S32: Unix Operations | T32: Unix Operations | V32: Anjali Jones | W32: 2024-03-28 11:09:17 | X32: 2026-05-07 11:09:17 | Y32: SCCM | Z32: Microsoft 365 | AA32: Video Conferencing | AB32: OneDrive for Business | AC32: Exchange Transport Service | AD32: 90 | AE32: Compliant | AF32: Missing owned_by
A33: 6716024727d84647bb4250776a076624 | B33: PC-0100014 | C33: cmdb_ci_pc_hardware | D33: AST-27615610 | E33: SN2370504045 | G33: Latitude 5540 | J33: Installed | K33: Operational | L33: 10.33.67.13 | O33: 8 | P33: 32 | Q33: 512 | R33: Pooja Krishnan | S33: Desktop Support | U33: Suresh Jones | V33: Suresh Williams | W33: 2022-04-24 11:09:17 | X33: 2026-05-14 11:09:17 | Y33: SCCM | Z33: Microsoft 365 | AA33: Internal Communications | AB33: Microsoft Purview | AC33: Microsoft Endpoint Manager | AD33: 60 | AE33: Partially Compliant | AF33: Missing manufacturer; Missing support_group; Missing location; Missing environment
A34: 283102dea02c413daf5a686e611824e1 | B34: PC-0100015 | C34: cmdb_ci_pc_hardware | D34: AST-72241165 | E34: SN9801437687 | G34: ThinkPad X1 Carbon | H34: Gurgaon-Office | I34: Production | L34: 10.27.78.199 | O34: 4 | P34: 8 | Q34: 256 | R34: Ravi Nair | S34: IT Service Desk | U34: Rajesh Singh | V34: David Nair | W34: 2023-08-02 11:09:17 | X34: 2024-12-19 11:09:17 | Y34: CSV Import | Z34: Microsoft 365 | AA34: Document Collaboration | AB34: Microsoft Teams | AC34: Exchange Transport Service | AD34: 50 | AE34: Non-Compliant | AF34: Missing operational_status; Missing install_status; Missing support_group; Missing manufacturer; Stale discovery (>90 days)
A35: 98e963bae5c84664803608c7c5ec46d9 | B35: lnx-dr-lon-00005 | C35: cmdb_ci_linux_server | D35: AST-32631985 | E35: SN9943858941 | H35: London-DR | I35: DR | J35: Installed | K35: Operational | L35: 10.197.23.109 | M35: Oracle Linux | N35: 8.7 | O35: 96 | P35: 768 | Q35: 2000 | S35: Platform Engineering | V35: Suresh Jones | W35: 2024-06-26 11:09:17 | X35: 2026-05-06 11:09:17 | Y35: Manual | Z35: Adobe | AA35: Digital Asset Management | AB35: Adobe Analytics | AC35: Adobe Cloud Storage | AD35: 60 | AE35: Partially Compliant | AF35: Missing manufacturer; Missing owned_by; Missing model_id; Missing support_group
A36: 9f659268a1924bce90c16f37a8c72388 | B36: AppSvc-0001 | C36: cmdb_ci_service_auto | D36: AST-10469596 | E36: SN4621129671 | F36: Internal | G36: Application Service | I36: DR | K36: Operational | S36: Application Support L2 | U36: Priya Sharma | V36: Mary Nair | W36: 2026-02-23 11:09:17 | X36: 2026-04-29 11:09:17 | Y36: ServiceNow Discovery | Z36: Microsoft 365 | AA36: Document Collaboration | AB36: OneDrive for Business | AC36: Exchange Transport Service | AD36: 70 | AE36: Partially Compliant | AF36: Missing location; Missing install_status; Missing support_group
A37: 228acb3610984eecabc01032384e04a8 | B37: win-tst-mum-00003 | C37: cmdb_ci_win_server | D37: AST-44687867 | E37: SN9635493133 | H37: Mumbai-DC2 | I37: Test | J37: Installed | K37: Operational | L37: 10.112.13.132 | M37: Windows Server | N37: 2022 Datacenter | O37: 16 | P37: 64 | Q37: 500 | S37: Windows Admins | T37: Windows Admins | U37: Anjali Patel | V37: Sunita Shetty | W37: 2025-06-01 11:09:17 | X37: 2026-05-14 11:09:17 | Y37: Service Mapping | Z37: SAP ERP | AA37: Record-to-Report | AB37: SAP Fiori Launchpad | AC37: SAP Gateway OData Service | AD37: 80 | AE37: Compliant | AF37: Missing model_id; Missing manufacturer
A38: 3bdd9a76d10849e1b201e8ea20804e74 | B38: PC-0100016 | C38: cmdb_ci_pc_hardware | D38: AST-42072501 | E38: SN4700789281 | F38: Lenovo | I38: Production | J38: Installed | L38: 10.41.11.77 | O38: 8 | P38: 32 | Q38: 512 | R38: James Krishnan | S38: End User Computing | T38: End User Computing | V38: Anand Banerjee | W38: 2023-01-04 11:09:17 | X38: 2026-05-15 11:09:17 | Y38: SCCM | Z38: Adobe | AA38: Digital Asset Management | AB38: Adobe Campaign | AC38: Adobe API Gateway | AD38: 60 | AE38: Partially Compliant | AF38: Missing owned_by; Missing model_id; Missing location; Missing operational_status
A39: 20beae7b97af45d1ae930d1150eb9f37 | B39: win-prd-ben-00004 | C39: cmdb_ci_win_server | D39: AST-21580293 | E39: SN1017288429 | F39: Lenovo | G39: ThinkSystem SR650 | H39: Bengaluru-DC1 | I39: Production | J39: Installed | K39: Operational | L39: 10.35.97.78 | M39: Windows Server | N39: 2022 Standard | O39: 4 | P39: 768 | Q39: 1000 | S39: Wintel Operations | T39: Wintel Operations | U39: Anjali Sharma | V39: Neha Mehta | W39: 2024-02-15 11:09:17 | X39: 2026-05-20 11:09:17 | Y39: ServiceNow Discovery | Z39: Oracle Fusion ERP | AA39: Project Portfolio Mgmt | AB39: Oracle Fusion Risk Mgmt | AC39: Oracle Integration Cloud | AD39: 100 | AE39: Compliant | AF39: None
A40: 5b3c9686e27b45d6835b60c2669163a2 | B40: db-dev-che-00001 | C40: cmdb_ci_db_instance | D40: AST-31801691 | E40: SN7388882254 | F40: Microsoft | G40: SQL Server 2019 | H40: Chennai-DC1 | I40: Development | J40: Installed | K40: Operational | L40: 10.179.198.35 | O40: 64 | P40: 32 | Q40: 4000 | S40: DBA - PostgreSQL | T40: DBA - PostgreSQL | U40: Vikram Patel | V40: Aditya Brown | W40: 2024-02-29 11:09:17 | X40: 2026-05-22 11:09:17 | Y40: ServiceNow Discovery | Z40: SAP ERP | AA40: Order-to-Cash | AB40: SAP S/4HANA Production | AC40: SAP NetWeaver Application Server | AD40: 100 | AE40: Compliant | AF40: None
...

Sheet CSDM v5 Mapping
A1: CSDM v5 Application & Service Mapping
A3: How the 5 Business Applications map to Business Services, Technical Applications, and Technical Services
A5: Business Application | B5: Business Services | C5: Technical Applications | D5: Technical Services
A6: Workday | B6: HR Self-Service • Talent Acquisition • Payroll Processing • Time & Attendance | C6: Workday HCM Core • Workday Payroll Engine • Workday Recruiting Portal • Workday Time Tracking • Workday Benefits Admin | D6: Identity Federation (SAML) • HR Data Integration Bus • Tenant API Gateway • Workday Reporting Service
A7: SAP ERP | B7: Order-to-Cash • Procure-to-Pay • Record-to-Report • Inventory & Warehouse • Production Planning | C7: SAP S/4HANA Finance • SAP S/4HANA Logistics • SAP S/4HANA Sales • SAP S/4HANA Procurement • SAP S/4HANA Production • SAP Fiori Launchpad | D7: SAP HANA Database • SAP NetWeaver Application Server • SAP Solution Manager • SAP Gateway OData Service • SAP PI/PO Integration
A8: Microsoft 365 | B8: Enterprise Email • Document Collaboration • Video Conferencing • Internal Communications • File Storage & Sync | C8: Exchange Online • SharePoint Online • Microsoft Teams • OneDrive for Business • Power Platform • Microsoft Purview | D8: Entra ID (Azure AD) • Microsoft Graph API • Exchange Transport Service • M365 Defender • Microsoft Endpoint Manager
A9: Adobe | B9: Content Authoring • Digital Asset Management • Marketing Automation • Web Analytics | C9: Adobe Creative Cloud • Adobe Experience Manager • Adobe Campaign • Adobe Analytics • Adobe Workfront | D9: Adobe Identity Management Service • Adobe Asset Service • Adobe Cloud Storage • Adobe API Gateway
A10: Oracle Fusion ERP | B10: Financial Close • Procurement Operations • Project Portfolio Mgmt • Risk & Compliance • Treasury Operations | C10: Oracle Fusion Financials • Oracle Fusion Procurement • Oracle Fusion Project Mgmt • Oracle Fusion Risk Mgmt • Oracle Fusion Tax Reporting | D10: Oracle Autonomous Database • Oracle Identity Cloud Service • Oracle Integration Cloud • Oracle Analytics Cloud • Oracle REST Data Service
A13: CSDM v5 5-Tier Alignment
A14: Tier 1 — Business Capability | B14: Strategic capability the organization needs (HR Operations, Finance Operations, etc.)
A15: Tier 2 — Business Application | B15: Workday, SAP ERP, Microsoft 365, Adobe, Oracle Fusion ERP (the 5 in this dataset)
A16: Tier 3 — Application Service / Technical Application | B16: cmdb_ci_service_auto — the runnable application service (e.g. SAP S/4HANA Finance)
A17: Tier 4 — Dynamic CI Group | B17: Query-based membership of supporting CIs (inferred from environment+application)
A18: Tier 5 — Component CIs | B18: The technical inventory rows in CMDB CIs sheet — servers, DBs, network, storage, PCs
A19: Business Service | B19: What the business consumer perceives (HR Self-Service, Order-to-Cash, etc.)
A20: Technical Service | B20: Underlying technical capability that supports the Business Service (Identity Federation, API Gateway, etc.)
